Workbook
Name CategoryList: Reference!$A$1:$A$6
Name Communities: Reference!$C$1:$C$16
Name Government: Reference!$D$1:$D$16
Name Our_People: Reference!$E$1:$E$10
Name Industry: Reference!$F$1:$F$8
Name Consumers: Reference!$G$1:$G$4
Name Investors: Reference!$H$1:$H$4
Name Markets: Reference!$J$1:$J$4
Name Regions: Reference!$K$1:$K$10
Name Geographies: Reference!$L$1:$L$4
Name Priorities: Reference!$M$1:$M$3
Name Statuses: Reference!$N$1:$N$4
Name ZoneGrid: Reference!$P$1:$S$6
Name RecTable: Reference!$U$1:$V$14

Sheet Intro
B1: STAKEHOLDR
B3: Stakeholders exist in a public square where ideas are exchanged, your credibility is won or lost, and value is created, shared, or squandered.
B5: How to plan for and engage stakeholders
B7: PURPOSE | D7: PLAN | F7: EXECUTE
B8: 1. Set goals for your organization | D8: 5. Landscape analysis | F8: 9. Launch campaign
B9: 2. Issue identification | D9: 6. Cross-functional teams alignment | F9: 10. Ongoing stakeholder analysis
B10: 3. Stakeholder identification | D10: 7. Research and listening sessions | F10: 11. Collaborate with stakeholders
B11: 4. Stakeholder prioritization | D11: 8. Early stakeholder analysis and modeling | F11: 12. Realize shared value where possible
B13: How to read the stakeholder map
B15: X Impact on the business: Negative impact ◀ ▶ Positive impact
B16: Y Influence in the community: Less influence ▼ ▲ Greater influence
B18: Proactively Defend | C18: Defend | D18: Protect | E18: Respond | F18: Identify | G18: Monitor | H18: Maintain
B19: Connect | C19: Commit | D19: Cooperate | E19: Collaborate | F19: Valuable Relationship | G19: High Value Relationship | H19: Strategic Partner
B21: NEGATIVE IMPACT ON ORGANIZATION | D21: THE WINNABLE MIDDLE | F21: POSITIVE IMPACT ON ORGANIZATION
B22: Defend license to operate | D22: Dispel myths and misperceptions | F22: Maximize shared value
B23: Challenge misinformation | D23: Appeal to their priorities | F23: Maintain relationship
B24: Plan for their influence in community | D24: Identify shared value to move them our way | F24: Champion their cause
B25: Identify their reputation with audiences | D25: Invest in relationship where possible | F25: Recruit as public surrogates
B26: “Influencer” | D26: Identify our reputation with them | F26: Communicate often
F27: “Influencer”
B29: The 14 zones at a glance
B31: Stakeholders are plotted on a two-axis grid: x measures impact on the business (do they work with you or against you?), y measures their influence in the community. The combination determines the relationship strategy.
B32: Proactively Defend | C32: Defend | D32: Valuable Relationship | E32: Strategic Partner
B33: Defend | C33: Protect | D33: Collaborate | E33: High Value Relationship
B34: Protect | C34: Respond | D34: Cooperate | E34: Collaborate
B35: Protect | C35: Respond | D35: Cooperate | E35: Collaborate
B36: Identify | C36: Identify | D36: Commit | E36: Commit
B37: Monitor | C37: Monitor | D37: Maintain | E37: Connect
B38: ← Works against you | C38: ↑ Greater community influence · ↓ Less community influence | E38: Works with you →
B40: Strategy reference
B42: For every zone, a stakeholder's position on the map returns a recommended posture and suggested immediate actions your team can take.
B43: Zone | C43: Tone | D43: Strategy and recommended action
B44: Proactively Defend | C44: Negative | D44: Address Key Influencer. Launch plan to neutralize a major threat to the industry or company's license to operate; leverage reputation, resources, subject-matter experts, and other allied stakeholders to win. Measure and report on activity often.
B45: Defend | C45: Negative | D45: Neutralize Threat. Defend license to operate. Defend reputation against regular attacks from stakeholders with high influence who are unlikely to move toward positive support; discredit message or position. Measure and report on activity often.
B46: Protect | C46: Negative | D46: Mobilize Defense. Take action with internal resources and strategy. Defend reputation against regular attacks; manage expectations for changing stakeholder dynamic or group's influence in the community. Measure and report on activity regularly.
B47: Respond | C47: Negative | D47: Challenge Stakeholder. Implement plan to challenge misinformation; reduce stakeholder's ability to destabilize the business or challenge brand identity and reputation.
B48: Identify | C48: Negative | D48: React To Issues Or Conflict. Work to neutralize threat; educate stakeholder; resolve or minimize the stakeholder's ability or willingness to maintain conflict. Assign internal staff, team, or working group to execute response.
B49: Monitor | C49: Winnable | D49: Plan Ahead, Listen. Map stakeholder and plan to respond in the event of change; assign internal staff, team, or working group to execute plan if necessary.
B50: Maintain | C50: Winnable | D50: Take Steps To Introduce Our Vision And Values. Take simple steps to engage; educate and create awareness about the business; look for ways to increase alignment and the stakeholder's influence over time.
B51: Connect | C51: Winnable | D51: Prioritize Resources Elsewhere. Take no action. Prioritize time and resources elsewhere but monitor for any negative changes in alignment or improved influence in the community over time.
...

Sheet Scoring
A1: # | B1: Stakeholder (from Workspace) | C1: Alex Rivera | E1: Jordan Kim | G1: Sam Okafor | I1: Priya Patel | K1: Devon Wright | M1: Weighted X | N1: Weighted Y
B2: Weights → | C2: 1.5 | E2: 1.2 | G2: 1 | I2: 0.8 | K2: 0.7 | M2: Sum w | N2: ==C2+E2+G2+I2+K2
A3: # | B3: Stakeholder | C3: x | D3: y | E3: x | F3: y | G3: x | H3: y | I3: x | J3: y | K3: x | L3: y
A4: 1 | B4: ==IF(Workspace!B2="","",Workspace!B2) | C4: 3 | D4: 8 | E4: 4 | F4: 9 | G4: 2 | H4: 8 | I4: 3 | J4: 8 | K4: 2 | L4: 7 | M4: ==IF(Workspace!B2="","",(C4*C$2+E4*E$2+G4*G$2+I4*I$2+K4*K$2)/(C2+E2+G2+I2+K2)) | N4: ==IF(Workspace!B2="","",(D4*C$2+F4*E$2+H4*G$2+J4*I$2+L4*K$2)/(C2+E2+G2+I2+K2))
A5: 2 | B5: ==IF(Workspace!B3="","",Workspace!B3) | C5: 7 | D5: 4 | E5: 8 | F5: 5 | G5: 7 | H5: 4 | I5: 6 | J5: 4 | K5: 6 | L5: 3 | M5: ==IF(Workspace!B3="","",(C5*C$2+E5*E$2+G5*G$2+I5*I$2+K5*K$2)/(C2+E2+G2+I2+K2)) | N5: ==IF(Workspace!B3="","",(D5*C$2+F5*E$2+H5*G$2+J5*I$2+L5*K$2)/(C2+E2+G2+I2+K2))
A6: 3 | B6: ==IF(Workspace!B4="","",Workspace!B4) | C6: -2 | D6: 7 | E6: -1 | F6: 8 | G6: -3 | H6: 7 | I6: -2 | J6: 8 | K6: -2 | L6: 7 | M6: ==IF(Workspace!B4="","",(C6*C$2+E6*E$2+G6*G$2+I6*I$2+K6*K$2)/(C2+E2+G2+I2+K2)) | N6: ==IF(Workspace!B4="","",(D6*C$2+F6*E$2+H6*G$2+J6*I$2+L6*K$2)/(C2+E2+G2+I2+K2))
A7: 4 | B7: ==IF(Workspace!B5="","",Workspace!B5) | C7: 1 | D7: 6 | E7: 2 | F7: 7 | G7: 1 | H7: 6 | I7: 0 | J7: 6 | K7: -1 | L7: 6 | M7: ==IF(Workspace!B5="","",(C7*C$2+E7*E$2+G7*G$2+I7*I$2+K7*K$2)/(C2+E2+G2+I2+K2)) | N7: ==IF(Workspace!B5="","",(D7*C$2+F7*E$2+H7*G$2+J7*I$2+L7*K$2)/(C2+E2+G2+I2+K2))
A8: 5 | B8: ==IF(Workspace!B6="","",Workspace!B6) | C8: 7 | D8: 9 | E8: 8 | F8: 9 | G8: 6 | H8: 8 | I8: 7 | J8: 9 | K8: 7 | L8: 9 | M8: ==IF(Workspace!B6="","",(C8*C$2+E8*E$2+G8*G$2+I8*I$2+K8*K$2)/(C2+E2+G2+I2+K2)) | N8: ==IF(Workspace!B6="","",(D8*C$2+F8*E$2+H8*G$2+J8*I$2+L8*K$2)/(C2+E2+G2+I2+K2))
A9: 6 | B9: ==IF(Workspace!B7="","",Workspace!B7) | C9: -8 | D9: 6 | E9: -9 | F9: 7 | G9: -7 | H9: 6 | I9: -8 | J9: 7 | K9: -9 | L9: 8 | M9: ==IF(Workspace!B7="","",(C9*C$2+E9*E$2+G9*G$2+I9*I$2+K9*K$2)/(C2+E2+G2+I2+K2)) | N9: ==IF(Workspace!B7="","",(D9*C$2+F9*E$2+H9*G$2+J9*I$2+L9*K$2)/(C2+E2+G2+I2+K2))
A10: 7 | B10: ==IF(Workspace!B8="","",Workspace!B8) | C10: -1 | D10: 9 | E10: 1 | F10: 9 | G10: 0 | H10: 9 | I10: -1 | J10: 9 | K10: 0 | L10: 10 | M10: ==IF(Workspace!B8="","",(C10*C$2+E10*E$2+G10*G$2+I10*I$2+K10*K$2)/(C2+E2+G2+I2+K2)) | N10: ==IF(Workspace!B8="","",(D10*C$2+F10*E$2+H10*G$2+J10*I$2+L10*K$2)/(C2+E2+G2+I2+K2))
A11: 8 | B11: ==IF(Workspace!B9="","",Workspace!B9) | C11: 6 | D11: 2 | E11: 7 | F11: 3 | G11: 8 | H11: 2 | I11: 6 | J11: 2 | K11: 6 | L11: 1 | M11: ==IF(Workspace!B9="","",(C11*C$2+E11*E$2+G11*G$2+I11*I$2+K11*K$2)/(C2+E2+G2+I2+K2)) | N11: ==IF(Workspace!B9="","",(D11*C$2+F11*E$2+H11*G$2+J11*I$2+L11*K$2)/(C2+E2+G2+I2+K2))
A12: 9 | B12: ==IF(Workspace!B10="","",Workspace!B10) | C12: 3 | D12: -3 | E12: 4 | F12: -2 | G12: 5 | H12: -3 | I12: 3 | J12: -3 | K12: 3 | L12: -4 | M12: ==IF(Workspace!B10="","",(C12*C$2+E12*E$2+G12*G$2+I12*I$2+K12*K$2)/(C2+E2+G2+I2+K2)) | N12: ==IF(Workspace!B10="","",(D12*C$2+F12*E$2+H12*G$2+J12*I$2+L12*K$2)/(C2+E2+G2+I2+K2))
A13: 10 | B13: ==IF(Workspace!B11="","",Workspace!B11) | C13: 6 | D13: 1 | E13: 7 | F13: 2 | G13: 8 | H13: 1 | I13: 6 | J13: 1 | K13: 6 | L13: 0 | M13: ==IF(Workspace!B11="","",(C13*C$2+E13*E$2+G13*G$2+I13*I$2+K13*K$2)/(C2+E2+G2+I2+K2)) | N13: ==IF(Workspace!B11="","",(D13*C$2+F13*E$2+H13*G$2+J13*I$2+L13*K$2)/(C2+E2+G2+I2+K2))
A14: 11 | B14: ==IF(Workspace!B12="","",Workspace!B12) | C14: 9 | D14: 7 | E14: 8 | F14: 6 | G14: 7 | H14: 5 | I14: 8 | J14: 6 | K14: 9 | L14: 7 | M14: ==IF(Workspace!B12="","",(C14*C$2+E14*E$2+G14*G$2+I14*I$2+K14*K$2)/(C2+E2+G2+I2+K2)) | N14: ==IF(Workspace!B12="","",(D14*C$2+F14*E$2+H14*G$2+J14*I$2+L14*K$2)/(C2+E2+G2+I2+K2))
A15: 12 | B15: ==IF(Workspace!B13="","",Workspace!B13) | C15: -7 | D15: 5 | E15: -6 | F15: 6 | G15: -5 | H15: 4 | I15: -7 | J15: 5 | K15: -8 | L15: 6 | M15: ==IF(Workspace!B13="","",(C15*C$2+E15*E$2+G15*G$2+I15*I$2+K15*K$2)/(C2+E2+G2+I2+K2)) | N15: ==IF(Workspace!B13="","",(D15*C$2+F15*E$2+H15*G$2+J15*I$2+L15*K$2)/(C2+E2+G2+I2+K2))
A16: 13 | B16: ==IF(Workspace!B14="","",Workspace!B14) | C16: 8 | D16: 0 | E16: 7 | F16: 1 | G16: 8 | H16: -1 | I16: 8 | J16: 0 | K16: 7 | L16: 0 | M16: ==IF(Workspace!B14="","",(C16*C$2+E16*E$2+G16*G$2+I16*I$2+K16*K$2)/(C2+E2+G2+I2+K2)) | N16: ==IF(Workspace!B14="","",(D16*C$2+F16*E$2+H16*G$2+J16*I$2+L16*K$2)/(C2+E2+G2+I2+K2))
A17: 14 | B17: ==IF(Workspace!B15="","",Workspace!B15) | C17: 10 | D17: 8 | E17: 9 | F17: 7 | G17: 9 | H17: 7 | I17: 10 | J17: 8 | K17: 10 | L17: 9 | M17: ==IF(Workspace!B15="","",(C17*C$2+E17*E$2+G17*G$2+I17*I$2+K17*K$2)/(C2+E2+G2+I2+K2)) | N17: ==IF(Workspace!B15="","",(D17*C$2+F17*E$2+H17*G$2+J17*I$2+L17*K$2)/(C2+E2+G2+I2+K2))
A18: 15 | B18: ==IF(Workspace!B16="","",Workspace!B16) | C18: 2 | D18: 9 | E18: 3 | F18: 10 | G18: 4 | H18: 9 | I18: 2 | J18: 9 | K18: 1 | L18: 9 | M18: ==IF(Workspace!B16="","",(C18*C$2+E18*E$2+G18*G$2+I18*I$2+K18*K$2)/(C2+E2+G2+I2+K2)) | N18: ==IF(Workspace!B16="","",(D18*C$2+F18*E$2+H18*G$2+J18*I$2+L18*K$2)/(C2+E2+G2+I2+K2))
A19: 16 | B19: ==IF(Workspace!B17="","",Workspace!B17) | C19: 4 | D19: 5 | E19: 5 | F19: 6 | G19: 3 | H19: 5 | I19: 4 | J19: 5 | K19: 4 | L19: 4 | M19: ==IF(Workspace!B17="","",(C19*C$2+E19*E$2+G19*G$2+I19*I$2+K19*K$2)/(C2+E2+G2+I2+K2)) | N19: ==IF(Workspace!B17="","",(D19*C$2+F19*E$2+H19*G$2+J19*I$2+L19*K$2)/(C2+E2+G2+I2+K2))
A20: 17 | B20: ==IF(Workspace!B18="","",Workspace!B18) | C20: -2 | D20: 9 | E20: -1 | F20: 10 | G20: -3 | H20: 9 | I20: -2 | J20: 10 | K20: -3 | L20: 9 | M20: ==IF(Workspace!B18="","",(C20*C$2+E20*E$2+G20*G$2+I20*I$2+K20*K$2)/(C2+E2+G2+I2+K2)) | N20: ==IF(Workspace!B18="","",(D20*C$2+F20*E$2+H20*G$2+J20*I$2+L20*K$2)/(C2+E2+G2+I2+K2))
A21: 18 | B21: ==IF(Workspace!B19="","",Workspace!B19) | C21: -5 | D21: 4 | E21: -4 | F21: 5 | G21: -4 | H21: 4 | I21: -5 | J21: 5 | K21: -6 | L21: 4 | M21: ==IF(Workspace!B19="","",(C21*C$2+E21*E$2+G21*G$2+I21*I$2+K21*K$2)/(C2+E2+G2+I2+K2)) | N21: ==IF(Workspace!B19="","",(D21*C$2+F21*E$2+H21*G$2+J21*I$2+L21*K$2)/(C2+E2+G2+I2+K2))
A22: 19 | B22: ==IF(Workspace!B20="","",Workspace!B20) | C22: 7 | D22: 6 | E22: 8 | F22: 7 | G22: 6 | H22: 6 | I22: 8 | J22: 7 | K22: 7 | L22: 6 | M22: ==IF(Workspace!B20="","",(C22*C$2+E22*E$2+G22*G$2+I22*I$2+K22*K$2)/(C2+E2+G2+I2+K2)) | N22: ==IF(Workspace!B20="","",(D22*C$2+F22*E$2+H22*G$2+J22*I$2+L22*K$2)/(C2+E2+G2+I2+K2))
A23: 20 | B23: ==IF(Workspace!B21="","",Workspace!B21) | C23: 3 | D23: 3 | E23: 4 | F23: 4 | G23: 5 | H23: 3 | I23: 3 | J23: 3 | K23: 3 | L23: 2 | M23: ==IF(Workspace!B21="","",(C23*C$2+E23*E$2+G23*G$2+I23*I$2+K23*K$2)/(C2+E2+G2+I2+K2)) | N23: ==IF(Workspace!B21="","",(D23*C$2+F23*E$2+H23*G$2+J23*I$2+L23*K$2)/(C2+E2+G2+I2+K2))
A24: 21 | B24: ==IF(Workspace!B22="","",Workspace!B22) | M24: ==IF(Workspace!B22="","",(C24*C$2+E24*E$2+G24*G$2+I24*I$2+K24*K$2)/(C2+E2+G2+I2+K2)) | N24: ==IF(Workspace!B22="","",(D24*C$2+F24*E$2+H24*G$2+J24*I$2+L24*K$2)/(C2+E2+G2+I2+K2))
A25: 22 | B25: ==IF(Workspace!B23="","",Workspace!B23) | M25: ==IF(Workspace!B23="","",(C25*C$2+E25*E$2+G25*G$2+I25*I$2+K25*K$2)/(C2+E2+G2+I2+K2)) | N25: ==IF(Workspace!B23="","",(D25*C$2+F25*E$2+H25*G$2+J25*I$2+L25*K$2)/(C2+E2+G2+I2+K2))
A26: 23 | B26: ==IF(Workspace!B24="","",Workspace!B24) | M26: ==IF(Workspace!B24="","",(C26*C$2+E26*E$2+G26*G$2+I26*I$2+K26*K$2)/(C2+E2+G2+I2+K2)) | N26: ==IF(Workspace!B24="","",(D26*C$2+F26*E$2+H26*G$2+J26*I$2+L26*K$2)/(C2+E2+G2+I2+K2))
A27: 24 | B27: ==IF(Workspace!B25="","",Workspace!B25) | M27: ==IF(Workspace!B25="","",(C27*C$2+E27*E$2+G27*G$2+I27*I$2+K27*K$2)/(C2+E2+G2+I2+K2)) | N27: ==IF(Workspace!B25="","",(D27*C$2+F27*E$2+H27*G$2+J27*I$2+L27*K$2)/(C2+E2+G2+I2+K2))
A28: 25 | B28: ==IF(Workspace!B26="","",Workspace!B26) | M28: ==IF(Workspace!B26="","",(C28*C$2+E28*E$2+G28*G$2+I28*I$2+K28*K$2)/(C2+E2+G2+I2+K2)) | N28: ==IF(Workspace!B26="","",(D28*C$2+F28*E$2+H28*G$2+J28*I$2+L28*K$2)/(C2+E2+G2+I2+K2))
A29: 26 | B29: ==IF(Workspace!B27="","",Workspace!B27) | M29: ==IF(Workspace!B27="","",(C29*C$2+E29*E$2+G29*G$2+I29*I$2+K29*K$2)/(C2+E2+G2+I2+K2)) | N29: ==IF(Workspace!B27="","",(D29*C$2+F29*E$2+H29*G$2+J29*I$2+L29*K$2)/(C2+E2+G2+I2+K2))
A30: 27 | B30: ==IF(Workspace!B28="","",Workspace!B28) | M30: ==IF(Workspace!B28="","",(C30*C$2+E30*E$2+G30*G$2+I30*I$2+K30*K$2)/(C2+E2+G2+I2+K2)) | N30: ==IF(Workspace!B28="","",(D30*C$2+F30*E$2+H30*G$2+J30*I$2+L30*K$2)/(C2+E2+G2+I2+K2))
A31: 28 | B31: ==IF(Workspace!B29="","",Workspace!B29) | M31: ==IF(Workspace!B29="","",(C31*C$2+E31*E$2+G31*G$2+I31*I$2+K31*K$2)/(C2+E2+G2+I2+K2)) | N31: ==IF(Workspace!B29="","",(D31*C$2+F31*E$2+H31*G$2+J31*I$2+L31*K$2)/(C2+E2+G2+I2+K2))
A32: 29 | B32: ==IF(Workspace!B30="","",Workspace!B30) | M32: ==IF(Workspace!B30="","",(C32*C$2+E32*E$2+G32*G$2+I32*I$2+K32*K$2)/(C2+E2+G2+I2+K2)) | N32: ==IF(Workspace!B30="","",(D32*C$2+F32*E$2+H32*G$2+J32*I$2+L32*K$2)/(C2+E2+G2+I2+K2))
A33: 30 | B33: ==IF(Workspace!B31="","",Workspace!B31) | M33: ==IF(Workspace!B31="","",(C33*C$2+E33*E$2+G33*G$2+I33*I$2+K33*K$2)/(C2+E2+G2+I2+K2)) | N33: ==IF(Workspace!B31="","",(D33*C$2+F33*E$2+H33*G$2+J33*I$2+L33*K$2)/(C2+E2+G2+I2+K2))

Sheet Workspace
A1: # | B1: Stakeholder | C1: Organization | D1: Category | E1: Type | F1: Market | G1: Region | H1: Geography | I1: State | J1: Site | K1: Priority | L1: x | M1: y | N1: Relationship | O1: Status | P1: Notes | Q1: xBand | R1: yBand
A2: 1 | B2: Mayor Maria Chen | C2: City of Cedarville | D2: Government | E2: Mayor | F2: Americas | G2: United States | H2: Local | I2: California | J2: Palo Alto, CA | K2: High | L2: ==IF(B2="","",Scoring!M4) | M2: ==IF(B2="","",Scoring!N4) | N2: ==IF(B2="","",INDEX(ZoneGrid,R2,Q2)) | O2: Active | P2: Generally supportive; cares about local jobs and waterfront access. | Q2: ==IF(B2="","",IF(L2<-5,1,IF(L2<0,2,IF(L2<5,3,4)))) | R2: ==IF(B2="","",IF(M2>5,1,IF(M2>2.5,2,IF(M2>0,3,IF(M2>-2.5,4,IF(M2>-5,5,6))))))
A3: 2 | B3: Cedarville Chamber | C3: Cedarville Chamber | D3: Communities | E3: Local Business | F3: Americas | G3: United States | H3: Local | K3: Medium | L3: ==IF(B3="","",Scoring!M5) | M3: ==IF(B3="","",Scoring!N5) | N3: ==IF(B3="","",INDEX(ZoneGrid,R3,Q3)) | O3: Active | P3: Strong partner on workforce initiatives. | Q3: ==IF(B3="","",IF(L3<-5,1,IF(L3<0,2,IF(L3<5,3,4)))) | R3: ==IF(B3="","",IF(M3>5,1,IF(M3>2.5,2,IF(M3>0,3,IF(M3>-2.5,4,IF(M3>-5,5,6))))))
A4: 3 | B4: Riverside Tribune | C4: Riverside Tribune | D4: Communities | E4: Media | F4: Americas | G4: United States | H4: Local | K4: High | L4: ==IF(B4="","",Scoring!M6) | M4: ==IF(B4="","",Scoring!N6) | N4: ==IF(B4="","",INDEX(ZoneGrid,R4,Q4)) | O4: Active | P4: Beat reporter looking for new angles on emissions story. | Q4: ==IF(B4="","",IF(L4<-5,1,IF(L4<0,2,IF(L4<5,3,4)))) | R4: ==IF(B4="","",IF(M4>5,1,IF(M4>2.5,2,IF(M4>0,3,IF(M4>-2.5,4,IF(M4>-5,5,6))))))
A5: 4 | B5: Local 412 Steelworkers | C5: Local 412 Steelworkers | D5: Industry | E5: Labor Union | F5: Americas | G5: United States | H5: Local | I5: Oregon | J5: Corvallis, OR | K5: High | L5: ==IF(B5="","",Scoring!M7) | M5: ==IF(B5="","",Scoring!N7) | N5: ==IF(B5="","",INDEX(ZoneGrid,R5,Q5)) | O5: Active | P5: Contract negotiations open in Q3. | Q5: ==IF(B5="","",IF(L5<-5,1,IF(L5<0,2,IF(L5<5,3,4)))) | R5: ==IF(B5="","",IF(M5>5,1,IF(M5>2.5,2,IF(M5>0,3,IF(M5>-2.5,4,IF(M5>-5,5,6))))))
A6: 5 | B6: Rep. James Park | C6: US House of Representatives | D6: Government | E6: US Congress | F6: Americas | G6: United States | H6: Federal | K6: High | L6: ==IF(B6="","",Scoring!M8) | M6: ==IF(B6="","",Scoring!N8) | N6: ==IF(B6="","",INDEX(ZoneGrid,R6,Q6)) | O6: Active | P6: Supportive on permitting reform. | Q6: ==IF(B6="","",IF(L6<-5,1,IF(L6<0,2,IF(L6<5,3,4)))) | R6: ==IF(B6="","",IF(M6>5,1,IF(M6>2.5,2,IF(M6>0,3,IF(M6>-2.5,4,IF(M6>-5,5,6))))))
A7: 6 | B7: Save Our River Coalition | C7: Save Our River Coalition | D7: Communities | E7: Activist Organization | F7: Americas | G7: United States | H7: Local | K7: High | L7: ==IF(B7="","",Scoring!M9) | M7: ==IF(B7="","",Scoring!N9) | N7: ==IF(B7="","",INDEX(ZoneGrid,R7,Q7)) | O7: Watch | P7: Filed FOIA on discharge permits in March. | Q7: ==IF(B7="","",IF(L7<-5,1,IF(L7<0,2,IF(L7<5,3,4)))) | R7: ==IF(B7="","",IF(M7>5,1,IF(M7>2.5,2,IF(M7>0,3,IF(M7>-2.5,4,IF(M7>-5,5,6))))))
A8: 7 | B8: State EPA | C8: State EPA | D8: Government | E8: Regulator (State) | F8: Americas | G8: United States | H8: State | K8: High | L8: ==IF(B8="","",Scoring!M10) | M8: ==IF(B8="","",Scoring!N10) | N8: ==IF(B8="","",INDEX(ZoneGrid,R8,Q8)) | O8: Active | P8: Air-permit renewal in review. | Q8: ==IF(B8="","",IF(L8<-5,1,IF(L8<0,2,IF(L8<5,3,4)))) | R8: ==IF(B8="","",IF(M8>5,1,IF(M8>2.5,2,IF(M8>0,3,IF(M8>-2.5,4,IF(M8>-5,5,6))))))
A9: 8 | B9: Pinewood Schools | C9: Pinewood Schools | D9: Communities | E9: K-12 Educator | F9: Americas | G9: United States | H9: Local | I9: Washington | J9: Vancouver, WA | K9: Medium | L9: ==IF(B9="","",Scoring!M11) | M9: ==IF(B9="","",Scoring!N11) | N9: ==IF(B9="","",INDEX(ZoneGrid,R9,Q9)) | O9: Active | P9: STEM partnership renewing this fall. | Q9: ==IF(B9="","",IF(L9<-5,1,IF(L9<0,2,IF(L9<5,3,4)))) | R9: ==IF(B9="","",IF(M9>5,1,IF(M9>2.5,2,IF(M9>0,3,IF(M9>-2.5,4,IF(M9>-5,5,6))))))
A10: 9 | B10: First Methodist | C10: First Methodist | D10: Communities | E10: Church | F10: Americas | G10: United States | H10: Local | K10: Low | L10: ==IF(B10="","",Scoring!M12) | M10: ==IF(B10="","",Scoring!N12) | N10: ==IF(B10="","",INDEX(ZoneGrid,R10,Q10)) | O10: Dormant | P10: Pastor open to facility tours. | Q10: ==IF(B10="","",IF(L10<-5,1,IF(L10<0,2,IF(L10<5,3,4)))) | R10: ==IF(B10="","",IF(M10>5,1,IF(M10>2.5,2,IF(M10>0,3,IF(M10>-2.5,4,IF(M10>-5,5,6))))))
A11: 10 | B11: VFW Post 117 | C11: VFW Post 117 | D11: Communities | E11: Veterans | F11: Americas | G11: United States | H11: Local | I11: Oregon | K11: Medium | L11: ==IF(B11="","",Scoring!M13) | M11: ==IF(B11="","",Scoring!N13) | N11: ==IF(B11="","",INDEX(ZoneGrid,R11,Q11)) | O11: Active | P11: Hosted community day in April. | Q11: ==IF(B11="","",IF(L11<-5,1,IF(L11<0,2,IF(L11<5,3,4)))) | R11: ==IF(B11="","",IF(M11>5,1,IF(M11>2.5,2,IF(M11>0,3,IF(M11>-2.5,4,IF(M11>-5,5,6))))))
A12: 11 | B12: Riverbend Hospital Board | C12: Riverbend Hospital Board | D12: Investors | E12: Board Member | F12: Americas | G12: United States | H12: Local | K12: High | L12: ==IF(B12="","",Scoring!M14) | M12: ==IF(B12="","",Scoring!N14) | N12: ==IF(B12="","",INDEX(ZoneGrid,R12,Q12)) | O12: Active | P12: Quarterly briefing scheduled. | Q12: ==IF(B12="","",IF(L12<-5,1,IF(L12<0,2,IF(L12<5,3,4)))) | R12: ==IF(B12="","",IF(M12>5,1,IF(M12>2.5,2,IF(M12>0,3,IF(M12>-2.5,4,IF(M12>-5,5,6))))))
A13: 12 | B13: Helios Capital | C13: Helios Capital | D13: Investors | E13: Activist Shareholder | F13: Americas | G13: United States | H13: National (all) | K13: High | L13: ==IF(B13="","",Scoring!M15) | M13: ==IF(B13="","",Scoring!N15) | N13: ==IF(B13="","",INDEX(ZoneGrid,R13,Q13)) | O13: Watch | P13: Submitted proxy proposal on board composition. | Q13: ==IF(B13="","",IF(L13<-5,1,IF(L13<0,2,IF(L13<5,3,4)))) | R13: ==IF(B13="","",IF(M13>5,1,IF(M13>2.5,2,IF(M13>0,3,IF(M13>-2.5,4,IF(M13>-5,5,6))))))
A14: 13 | B14: Bayside Distribution | C14: Bayside Distribution | D14: Industry | E14: Channel Partners | F14: Americas | G14: United States | H14: National (all) | K14: Medium | L14: ==IF(B14="","",Scoring!M16) | M14: ==IF(B14="","",Scoring!N16) | N14: ==IF(B14="","",INDEX(ZoneGrid,R14,Q14)) | O14: Active | P14: Renewing distribution contract. | Q14: ==IF(B14="","",IF(L14<-5,1,IF(L14<0,2,IF(L14<5,3,4)))) | R14: ==IF(B14="","",IF(M14>5,1,IF(M14>2.5,2,IF(M14>0,3,IF(M14>-2.5,4,IF(M14>-5,5,6))))))
A15: 14 | B15: Sarah Voss | C15: Internal Operations | D15: Our People | E15: Executive | F15: Americas | G15: United States | H15: National (all) | K15: High | L15: ==IF(B15="","",Scoring!M17) | M15: ==IF(B15="","",Scoring!N17) | N15: ==IF(B15="","",INDEX(ZoneGrid,R15,Q15)) | O15: Active | P15: VP Ops; champion for plant modernization. | Q15: ==IF(B15="","",IF(L15<-5,1,IF(L15<0,2,IF(L15<5,3,4)))) | R15: ==IF(B15="","",IF(M15>5,1,IF(M15>2.5,2,IF(M15>0,3,IF(M15>-2.5,4,IF(M15>-5,5,6))))))
A16: 15 | B16: Cedar Valley Tribes Council | C16: Cedar Valley Tribes Council | D16: Communities | E16: Tribes | F16: Americas | G16: United States | H16: Federal | K16: High | L16: ==IF(B16="","",Scoring!M18) | M16: ==IF(B16="","",Scoring!N18) | N16: ==IF(B16="","",INDEX(ZoneGrid,R16,Q16)) | O16: Active | P16: Consultation on watershed plan ongoing. | Q16: ==IF(B16="","",IF(L16<-5,1,IF(L16<0,2,IF(L16<5,3,4)))) | R16: ==IF(B16="","",IF(M16>5,1,IF(M16>2.5,2,IF(M16>0,3,IF(M16>-2.5,4,IF(M16>-5,5,6))))))
A17: 16 | B17: County Supervisor Elena Reyes | C17: Cedarville County | D17: Government | E17: County Supervisor | F17: Americas | G17: United States | H17: Local | I17: Texas | J17: Houston, TX | K17: Medium | L17: ==IF(B17="","",Scoring!M19) | M17: ==IF(B17="","",Scoring!N19) | N17: ==IF(B17="","",INDEX(ZoneGrid,R17,Q17)) | O17: Active | P17: Up for re-election in November. | Q17: ==IF(B17="","",IF(L17<-5,1,IF(L17<0,2,IF(L17<5,3,4)))) | R17: ==IF(B17="","",IF(M17>5,1,IF(M17>2.5,2,IF(M17>0,3,IF(M17>-2.5,4,IF(M17>-5,5,6))))))
A18: 17 | B18: European Commission DG ENV | C18: European Commission DG ENV | D18: Government | E18: Regulator (Federal) | F18: EMEA | G18: Europe | H18: National (all) | K18: High | L18: ==IF(B18="","",Scoring!M20) | M18: ==IF(B18="","",Scoring!N20) | N18: ==IF(B18="","",INDEX(ZoneGrid,R18,Q18)) | O18: Active | P18: Sustainability disclosure rules in consultation. | Q18: ==IF(B18="","",IF(L18<-5,1,IF(L18<0,2,IF(L18<5,3,4)))) | R18: ==IF(B18="","",IF(M18>5,1,IF(M18>2.5,2,IF(M18>0,3,IF(M18>-2.5,4,IF(M18>-5,5,6))))))
A19: 18 | B19: BUND Germany | C19: BUND Germany | D19: Communities | E19: NGO | F19: EMEA | G19: Europe | H19: National (all) | K19: Medium | L19: ==IF(B19="","",Scoring!M21) | M19: ==IF(B19="","",Scoring!N21) | N19: ==IF(B19="","",INDEX(ZoneGrid,R19,Q19)) | O19: Active | P19: Coalition partner on packaging directive. | Q19: ==IF(B19="","",IF(L19<-5,1,IF(L19<0,2,IF(L19<5,3,4)))) | R19: ==IF(B19="","",IF(M19>5,1,IF(M19>2.5,2,IF(M19>0,3,IF(M19>-2.5,4,IF(M19>-5,5,6))))))
A20: 19 | B20: DigitalEurope | C20: DigitalEurope | D20: Industry | E20: Trade Association | F20: EMEA | G20: Europe | H20: National (all) | K20: High | L20: ==IF(B20="","",Scoring!M22) | M20: ==IF(B20="","",Scoring!N22) | N20: ==IF(B20="","",INDEX(ZoneGrid,R20,Q20)) | O20: Active | P20: Working group lead on AI Act compliance. | Q20: ==IF(B20="","",IF(L20<-5,1,IF(L20<0,2,IF(L20<5,3,4)))) | R20: ==IF(B20="","",IF(M20>5,1,IF(M20>2.5,2,IF(M20>0,3,IF(M20>-2.5,4,IF(M20>-5,5,6))))))
A21: 20 | B21: Brazilian E-Waste Coalition | C21: Brazilian E-Waste Coalition | D21: Communities | E21: NGO | F21: LATAM | G21: Brazil | H21: National (all) | K21: Medium | L21: ==IF(B21="","",Scoring!M23) | M21: ==IF(B21="","",Scoring!N23) | N21: ==IF(B21="","",INDEX(ZoneGrid,R21,Q21)) | O21: Active | P21: Supplies take-back program partner. | Q21: ==IF(B21="","",IF(L21<-5,1,IF(L21<0,2,IF(L21<5,3,4)))) | R21: ==IF(B21="","",IF(M21>5,1,IF(M21>2.5,2,IF(M21>0,3,IF(M21>-2.5,4,IF(M21>-5,5,6))))))
A22: 21 | L22: ==IF(B22="","",Scoring!M24) | M22: ==IF(B22="","",Scoring!N24) | N22: ==IF(B22="","",INDEX(ZoneGrid,R22,Q22)) | Q22: ==IF(B22="","",IF(L22<-5,1,IF(L22<0,2,IF(L22<5,3,4)))) | R22: ==IF(B22="","",IF(M22>5,1,IF(M22>2.5,2,IF(M22>0,3,IF(M22>-2.5,4,IF(M22>-5,5,6))))))
A23: 22 | L23: ==IF(B23="","",Scoring!M25) | M23: ==IF(B23="","",Scoring!N25) | N23: ==IF(B23="","",INDEX(ZoneGrid,R23,Q23)) | Q23: ==IF(B23="","",IF(L23<-5,1,IF(L23<0,2,IF(L23<5,3,4)))) | R23: ==IF(B23="","",IF(M23>5,1,IF(M23>2.5,2,IF(M23>0,3,IF(M23>-2.5,4,IF(M23>-5,5,6))))))
A24: 23 | L24: ==IF(B24="","",Scoring!M26) | M24: ==IF(B24="","",Scoring!N26) | N24: ==IF(B24="","",INDEX(ZoneGrid,R24,Q24)) | Q24: ==IF(B24="","",IF(L24<-5,1,IF(L24<0,2,IF(L24<5,3,4)))) | R24: ==IF(B24="","",IF(M24>5,1,IF(M24>2.5,2,IF(M24>0,3,IF(M24>-2.5,4,IF(M24>-5,5,6))))))
A25: 24 | L25: ==IF(B25="","",Scoring!M27) | M25: ==IF(B25="","",Scoring!N27) | N25: ==IF(B25="","",INDEX(ZoneGrid,R25,Q25)) | Q25: ==IF(B25="","",IF(L25<-5,1,IF(L25<0,2,IF(L25<5,3,4)))) | R25: ==IF(B25="","",IF(M25>5,1,IF(M25>2.5,2,IF(M25>0,3,IF(M25>-2.5,4,IF(M25>-5,5,6))))))
A26: 25 | L26: ==IF(B26="","",Scoring!M28) | M26: ==IF(B26="","",Scoring!N28) | N26: ==IF(B26="","",INDEX(ZoneGrid,R26,Q26)) | Q26: ==IF(B26="","",IF(L26<-5,1,IF(L26<0,2,IF(L26<5,3,4)))) | R26: ==IF(B26="","",IF(M26>5,1,IF(M26>2.5,2,IF(M26>0,3,IF(M26>-2.5,4,IF(M26>-5,5,6))))))
A27: 26 | L27: ==IF(B27="","",Scoring!M29) | M27: ==IF(B27="","",Scoring!N29) | N27: ==IF(B27="","",INDEX(ZoneGrid,R27,Q27)) | Q27: ==IF(B27="","",IF(L27<-5,1,IF(L27<0,2,IF(L27<5,3,4)))) | R27: ==IF(B27="","",IF(M27>5,1,IF(M27>2.5,2,IF(M27>0,3,IF(M27>-2.5,4,IF(M27>-5,5,6))))))
A28: 27 | L28: ==IF(B28="","",Scoring!M30) | M28: ==IF(B28="","",Scoring!N30) | N28: ==IF(B28="","",INDEX(ZoneGrid,R28,Q28)) | Q28: ==IF(B28="","",IF(L28<-5,1,IF(L28<0,2,IF(L28<5,3,4)))) | R28: ==IF(B28="","",IF(M28>5,1,IF(M28>2.5,2,IF(M28>0,3,IF(M28>-2.5,4,IF(M28>-5,5,6))))))
A29: 28 | L29: ==IF(B29="","",Scoring!M31) | M29: ==IF(B29="","",Scoring!N31) | N29: ==IF(B29="","",INDEX(ZoneGrid,R29,Q29)) | Q29: ==IF(B29="","",IF(L29<-5,1,IF(L29<0,2,IF(L29<5,3,4)))) | R29: ==IF(B29="","",IF(M29>5,1,IF(M29>2.5,2,IF(M29>0,3,IF(M29>-2.5,4,IF(M29>-5,5,6))))))
A30: 29 | L30: ==IF(B30="","",Scoring!M32) | M30: ==IF(B30="","",Scoring!N32) | N30: ==IF(B30="","",INDEX(ZoneGrid,R30,Q30)) | Q30: ==IF(B30="","",IF(L30<-5,1,IF(L30<0,2,IF(L30<5,3,4)))) | R30: ==IF(B30="","",IF(M30>5,1,IF(M30>2.5,2,IF(M30>0,3,IF(M30>-2.5,4,IF(M30>-5,5,6))))))
A31: 30 | L31: ==IF(B31="","",Scoring!M33) | M31: ==IF(B31="","",Scoring!N33) | N31: ==IF(B31="","",INDEX(ZoneGrid,R31,Q31)) | Q31: ==IF(B31="","",IF(L31<-5,1,IF(L31<0,2,IF(L31<5,3,4)))) | R31: ==IF(B31="","",IF(M31>5,1,IF(M31>2.5,2,IF(M31>0,3,IF(M31>-2.5,4,IF(M31>-5,5,6))))))

Sheet Map
A1: STAKEHOLDR MAP | H1: Focus a stakeholder (Excel can't hover the map, so pick one here to isolate its zone and recommendation):
H2: Mayor Maria Chen | J2: ==IFERROR("x "&TEXT(INDEX(Workspace!$L$2:$L$31,MATCH($H$2,Workspace!$B$2:$B$31,0)),"0.0")&" y "&TEXT(INDEX(Workspace!$M$2:$M$31,MATCH($H$2,Workspace!$B$2:$B$31,0)),"0.0"),"") | L2: ==IFERROR(INDEX(Workspace!$N$2:$N$31,MATCH($H$2,Workspace!$B$2:$B$31,0)),"")
C3: IMPACT ON THE BUSINESS ▶ | H3: ==IFERROR("Recommendation: "&VLOOKUP(INDEX(Workspace!$N$2:$N$31,MATCH($H$2,Workspace!$B$2:$B$31,0)),RecTable,2,FALSE),"")
C4: x < -5 | D4: -5 to 0 | E4: 0 to 5 | F4: x > 5 | H4: Stakeholder | I4: x | J4: y | K4: Relationship | L4: Recommendation
A5: INFLUENCE IN THE COMMUNITY ▲ | B5: y > 5 | C5: =="Proactively Defend"&IF(TEXTJOIN(CHAR(10),TRUE,IF((Workspace!$Q$2:$Q$31=1)*(Workspace!$R$2:$R$31=1),Workspace!$B$2:$B$31,""))="","",CHAR(10)&TEXTJOIN(CHAR(10),TRUE,IF((Workspace!$Q$2:$Q$31=1)*(Workspace!$R$2:$R$31=1),Workspace!$B$2:$B$31,""))) | D5: =="Defend"&IF(TEXTJOIN(CHAR(10),TRUE,IF((Workspace!$Q$2:$Q$31=2)*(Workspace!$R$2:$R$31=1),Workspace!$B$2:$B$31,""))="","",CHAR(10)&TEXTJOIN(CHAR(10),TRUE,IF((Workspace!$Q$2:$Q$31=2)*(Workspace!$R$2:$R$31=1),Workspace!$B$2:$B$31,""))) | E5: =="Valuable Relationship"&IF(TEXTJOIN(CHAR(10),TRUE,IF((Workspace!$Q$2:$Q$31=3)*(Workspace!$R$2:$R$31=1),Workspace!$B$2:$B$31,""))="","",CHAR(10)&TEXTJOIN(CHAR(10),TRUE,IF((Workspace!$Q$2:$Q$31=3)*(Workspace!$R$2:$R$31=1),Workspace!$B$2:$B$31,""))) | F5: =="Strategic Partner"&IF(TEXTJOIN(CHAR(10),TRUE,IF((Workspace!$Q$2:$Q$31=4)*(Workspace!$R$2:$R$31=1),Workspace!$B$2:$B$31,""))="","",CHAR(10)&TEXTJOIN(CHAR(10),TRUE,IF((Workspace!$Q$2:$Q$31=4)*(Workspace!$R$2:$R$31=1),Workspace!$B$2:$B$31,""))) | H5: ==IF(Workspace!B2="","",Workspace!B2) | I5: ==IF(Workspace!B2="","",Workspace!L2) | J5: ==IF(Workspace!B2="","",Workspace!M2) | K5: ==IF(Workspace!B2="","",Workspace!N2) | L5: ==IF(Workspace!B2="","",VLOOKUP(Workspace!N2,RecTable,2,FALSE))
B6: 2.5 to 5 | C6: =="Defend"&IF(TEXTJOIN(CHAR(10),TRUE,IF((Workspace!$Q$2:$Q$31=1)*(Workspace!$R$2:$R$31=2),Workspace!$B$2:$B$31,""))="","",CHAR(10)&TEXTJOIN(CHAR(10),TRUE,IF((Workspace!$Q$2:$Q$31=1)*(Workspace!$R$2:$R$31=2),Workspace!$B$2:$B$31,""))) | D6: =="Protect"&IF(TEXTJOIN(CHAR(10),TRUE,IF((Workspace!$Q$2:$Q$31=2)*(Workspace!$R$2:$R$31=2),Workspace!$B$2:$B$31,""))="","",CHAR(10)&TEXTJOIN(CHAR(10),TRUE,IF((Workspace!$Q$2:$Q$31=2)*(Workspace!$R$2:$R$31=2),Workspace!$B$2:$B$31,""))) | E6: =="Collaborate"&IF(TEXTJOIN(CHAR(10),TRUE,IF((Workspace!$Q$2:$Q$31=3)*(Workspace!$R$2:$R$31=2),Workspace!$B$2:$B$31,""))="","",CHAR(10)&TEXTJOIN(CHAR(10),TRUE,IF((Workspace!$Q$2:$Q$31=3)*(Workspace!$R$2:$R$31=2),Workspace!$B$2:$B$31,""))) | F6: =="High Value Relationship"&IF(TEXTJOIN(CHAR(10),TRUE,IF((Workspace!$Q$2:$Q$31=4)*(Workspace!$R$2:$R$31=2),Workspace!$B$2:$B$31,""))="","",CHAR(10)&TEXTJOIN(CHAR(10),TRUE,IF((Workspace!$Q$2:$Q$31=4)*(Workspace!$R$2:$R$31=2),Workspace!$B$2:$B$31,""))) | H6: ==IF(Workspace!B3="","",Workspace!B3) | I6: ==IF(Workspace!B3="","",Workspace!L3) | J6: ==IF(Workspace!B3="","",Workspace!M3) | K6: ==IF(Workspace!B3="","",Workspace!N3) | L6: ==IF(Workspace!B3="","",VLOOKUP(Workspace!N3,RecTable,2,FALSE))
B7: 0 to 2.5 | C7: =="Protect"&IF(TEXTJOIN(CHAR(10),TRUE,IF((Workspace!$Q$2:$Q$31=1)*(Workspace!$R$2:$R$31=3),Workspace!$B$2:$B$31,""))="","",CHAR(10)&TEXTJOIN(CHAR(10),TRUE,IF((Workspace!$Q$2:$Q$31=1)*(Workspace!$R$2:$R$31=3),Workspace!$B$2:$B$31,""))) | D7: =="Respond"&IF(TEXTJOIN(CHAR(10),TRUE,IF((Workspace!$Q$2:$Q$31=2)*(Workspace!$R$2:$R$31=3),Workspace!$B$2:$B$31,""))="","",CHAR(10)&TEXTJOIN(CHAR(10),TRUE,IF((Workspace!$Q$2:$Q$31=2)*(Workspace!$R$2:$R$31=3),Workspace!$B$2:$B$31,""))) | E7: =="Cooperate"&IF(TEXTJOIN(CHAR(10),TRUE,IF((Workspace!$Q$2:$Q$31=3)*(Workspace!$R$2:$R$31=3),Workspace!$B$2:$B$31,""))="","",CHAR(10)&TEXTJOIN(CHAR(10),TRUE,IF((Workspace!$Q$2:$Q$31=3)*(Workspace!$R$2:$R$31=3),Workspace!$B$2:$B$31,""))) | F7: =="Collaborate"&IF(TEXTJOIN(CHAR(10),TRUE,IF((Workspace!$Q$2:$Q$31=4)*(Workspace!$R$2:$R$31=3),Workspace!$B$2:$B$31,""))="","",CHAR(10)&TEXTJOIN(CHAR(10),TRUE,IF((Workspace!$Q$2:$Q$31=4)*(Workspace!$R$2:$R$31=3),Workspace!$B$2:$B$31,""))) | H7: ==IF(Workspace!B4="","",Workspace!B4) | I7: ==IF(Workspace!B4="","",Workspace!L4) | J7: ==IF(Workspace!B4="","",Workspace!M4) | K7: ==IF(Workspace!B4="","",Workspace!N4) | L7: ==IF(Workspace!B4="","",VLOOKUP(Workspace!N4,RecTable,2,FALSE))
B8: -2.5 to 0 | C8: =="Protect"&IF(TEXTJOIN(CHAR(10),TRUE,IF((Workspace!$Q$2:$Q$31=1)*(Workspace!$R$2:$R$31=4),Workspace!$B$2:$B$31,""))="","",CHAR(10)&TEXTJOIN(CHAR(10),TRUE,IF((Workspace!$Q$2:$Q$31=1)*(Workspace!$R$2:$R$31=4),Workspace!$B$2:$B$31,""))) | D8: =="Respond"&IF(TEXTJOIN(CHAR(10),TRUE,IF((Workspace!$Q$2:$Q$31=2)*(Workspace!$R$2:$R$31=4),Workspace!$B$2:$B$31,""))="","",CHAR(10)&TEXTJOIN(CHAR(10),TRUE,IF((Workspace!$Q$2:$Q$31=2)*(Workspace!$R$2:$R$31=4),Workspace!$B$2:$B$31,""))) | E8: =="Cooperate"&IF(TEXTJOIN(CHAR(10),TRUE,IF((Workspace!$Q$2:$Q$31=3)*(Workspace!$R$2:$R$31=4),Workspace!$B$2:$B$31,""))="","",CHAR(10)&TEXTJOIN(CHAR(10),TRUE,IF((Workspace!$Q$2:$Q$31=3)*(Workspace!$R$2:$R$31=4),Workspace!$B$2:$B$31,""))) | F8: =="Collaborate"&IF(TEXTJOIN(CHAR(10),TRUE,IF((Workspace!$Q$2:$Q$31=4)*(Workspace!$R$2:$R$31=4),Workspace!$B$2:$B$31,""))="","",CHAR(10)&TEXTJOIN(CHAR(10),TRUE,IF((Workspace!$Q$2:$Q$31=4)*(Workspace!$R$2:$R$31=4),Workspace!$B$2:$B$31,""))) | H8: ==IF(Workspace!B5="","",Workspace!B5) | I8: ==IF(Workspace!B5="","",Workspace!L5) | J8: ==IF(Workspace!B5="","",Workspace!M5) | K8: ==IF(Workspace!B5="","",Workspace!N5) | L8: ==IF(Workspace!B5="","",VLOOKUP(Workspace!N5,RecTable,2,FALSE))
B9: -5 to -2.5 | C9: =="Identify"&IF(TEXTJOIN(CHAR(10),TRUE,IF((Workspace!$Q$2:$Q$31=1)*(Workspace!$R$2:$R$31=5),Workspace!$B$2:$B$31,""))="","",CHAR(10)&TEXTJOIN(CHAR(10),TRUE,IF((Workspace!$Q$2:$Q$31=1)*(Workspace!$R$2:$R$31=5),Workspace!$B$2:$B$31,""))) | D9: =="Identify"&IF(TEXTJOIN(CHAR(10),TRUE,IF((Workspace!$Q$2:$Q$31=2)*(Workspace!$R$2:$R$31=5),Workspace!$B$2:$B$31,""))="","",CHAR(10)&TEXTJOIN(CHAR(10),TRUE,IF((Workspace!$Q$2:$Q$31=2)*(Workspace!$R$2:$R$31=5),Workspace!$B$2:$B$31,""))) | E9: =="Commit"&IF(TEXTJOIN(CHAR(10),TRUE,IF((Workspace!$Q$2:$Q$31=3)*(Workspace!$R$2:$R$31=5),Workspace!$B$2:$B$31,""))="","",CHAR(10)&TEXTJOIN(CHAR(10),TRUE,IF((Workspace!$Q$2:$Q$31=3)*(Workspace!$R$2:$R$31=5),Workspace!$B$2:$B$31,""))) | F9: =="Commit"&IF(TEXTJOIN(CHAR(10),TRUE,IF((Workspace!$Q$2:$Q$31=4)*(Workspace!$R$2:$R$31=5),Workspace!$B$2:$B$31,""))="","",CHAR(10)&TEXTJOIN(CHAR(10),TRUE,IF((Workspace!$Q$2:$Q$31=4)*(Workspace!$R$2:$R$31=5),Workspace!$B$2:$B$31,""))) | H9: ==IF(Workspace!B6="","",Workspace!B6) | I9: ==IF(Workspace!B6="","",Workspace!L6) | J9: ==IF(Workspace!B6="","",Workspace!M6) | K9: ==IF(Workspace!B6="","",Workspace!N6) | L9: ==IF(Workspace!B6="","",VLOOKUP(Workspace!N6,RecTable,2,FALSE))
B10: y < -5 | C10: =="Monitor"&IF(TEXTJOIN(CHAR(10),TRUE,IF((Workspace!$Q$2:$Q$31=1)*(Workspace!$R$2:$R$31=6),Workspace!$B$2:$B$31,""))="","",CHAR(10)&TEXTJOIN(CHAR(10),TRUE,IF((Workspace!$Q$2:$Q$31=1)*(Workspace!$R$2:$R$31=6),Workspace!$B$2:$B$31,""))) | D10: =="Monitor"&IF(TEXTJOIN(CHAR(10),TRUE,IF((Workspace!$Q$2:$Q$31=2)*(Workspace!$R$2:$R$31=6),Workspace!$B$2:$B$31,""))="","",CHAR(10)&TEXTJOIN(CHAR(10),TRUE,IF((Workspace!$Q$2:$Q$31=2)*(Workspace!$R$2:$R$31=6),Workspace!$B$2:$B$31,""))) | E10: =="Maintain"&IF(TEXTJOIN(CHAR(10),TRUE,IF((Workspace!$Q$2:$Q$31=3)*(Workspace!$R$2:$R$31=6),Workspace!$B$2:$B$31,""))="","",CHAR(10)&TEXTJOIN(CHAR(10),TRUE,IF((Workspace!$Q$2:$Q$31=3)*(Workspace!$R$2:$R$31=6),Workspace!$B$2:$B$31,""))) | F10: =="Connect"&IF(TEXTJOIN(CHAR(10),TRUE,IF((Workspace!$Q$2:$Q$31=4)*(Workspace!$R$2:$R$31=6),Workspace!$B$2:$B$31,""))="","",CHAR(10)&TEXTJOIN(CHAR(10),TRUE,IF((Workspace!$Q$2:$Q$31=4)*(Workspace!$R$2:$R$31=6),Workspace!$B$2:$B$31,""))) | H10: ==IF(Workspace!B7="","",Workspace!B7) | I10: ==IF(Workspace!B7="","",Workspace!L7) | J10: ==IF(Workspace!B7="","",Workspace!M7) | K10: ==IF(Workspace!B7="","",Workspace!N7) | L10: ==IF(Workspace!B7="","",VLOOKUP(Workspace!N7,RecTable,2,FALSE))
H11: ==IF(Workspace!B8="","",Workspace!B8) | I11: ==IF(Workspace!B8="","",Workspace!L8) | J11: ==IF(Workspace!B8="","",Workspace!M8) | K11: ==IF(Workspace!B8="","",Workspace!N8) | L11: ==IF(Workspace!B8="","",VLOOKUP(Workspace!N8,RecTable,2,FALSE))
C12: ← Works against you | D12: ↑ Greater community influence · ↓ Less community influence | F12: Works with you → | H12: ==IF(Workspace!B9="","",Workspace!B9) | I12: ==IF(Workspace!B9="","",Workspace!L9) | J12: ==IF(Workspace!B9="","",Workspace!M9) | K12: ==IF(Workspace!B9="","",Workspace!N9) | L12: ==IF(Workspace!B9="","",VLOOKUP(Workspace!N9,RecTable,2,FALSE))
H13: ==IF(Workspace!B10="","",Workspace!B10) | I13: ==IF(Workspace!B10="","",Workspace!L10) | J13: ==IF(Workspace!B10="","",Workspace!M10) | K13: ==IF(Workspace!B10="","",Workspace!N10) | L13: ==IF(Workspace!B10="","",VLOOKUP(Workspace!N10,RecTable,2,FALSE))
H14: ==IF(Workspace!B11="","",Workspace!B11) | I14: ==IF(Workspace!B11="","",Workspace!L11) | J14: ==IF(Workspace!B11="","",Workspace!M11) | K14: ==IF(Workspace!B11="","",Workspace!N11) | L14: ==IF(Workspace!B11="","",VLOOKUP(Workspace!N11,RecTable,2,FALSE))
H15: ==IF(Workspace!B12="","",Workspace!B12) | I15: ==IF(Workspace!B12="","",Workspace!L12) | J15: ==IF(Workspace!B12="","",Workspace!M12) | K15: ==IF(Workspace!B12="","",Workspace!N12) | L15: ==IF(Workspace!B12="","",VLOOKUP(Workspace!N12,RecTable,2,FALSE))
H16: ==IF(Workspace!B13="","",Workspace!B13) | I16: ==IF(Workspace!B13="","",Workspace!L13) | J16: ==IF(Workspace!B13="","",Workspace!M13) | K16: ==IF(Workspace!B13="","",Workspace!N13) | L16: ==IF(Workspace!B13="","",VLOOKUP(Workspace!N13,RecTable,2,FALSE))
H17: ==IF(Workspace!B14="","",Workspace!B14) | I17: ==IF(Workspace!B14="","",Workspace!L14) | J17: ==IF(Workspace!B14="","",Workspace!M14) | K17: ==IF(Workspace!B14="","",Workspace!N14) | L17: ==IF(Workspace!B14="","",VLOOKUP(Workspace!N14,RecTable,2,FALSE))
H18: ==IF(Workspace!B15="","",Workspace!B15) | I18: ==IF(Workspace!B15="","",Workspace!L15) | J18: ==IF(Workspace!B15="","",Workspace!M15) | K18: ==IF(Workspace!B15="","",Workspace!N15) | L18: ==IF(Workspace!B15="","",VLOOKUP(Workspace!N15,RecTable,2,FALSE))
H19: ==IF(Workspace!B16="","",Workspace!B16) | I19: ==IF(Workspace!B16="","",Workspace!L16) | J19: ==IF(Workspace!B16="","",Workspace!M16) | K19: ==IF(Workspace!B16="","",Workspace!N16) | L19: ==IF(Workspace!B16="","",VLOOKUP(Workspace!N16,RecTable,2,FALSE))
H20: ==IF(Workspace!B17="","",Workspace!B17) | I20: ==IF(Workspace!B17="","",Workspace!L17) | J20: ==IF(Workspace!B17="","",Workspace!M17) | K20: ==IF(Workspace!B17="","",Workspace!N17) | L20: ==IF(Workspace!B17="","",VLOOKUP(Workspace!N17,RecTable,2,FALSE))
H21: ==IF(Workspace!B18="","",Workspace!B18) | I21: ==IF(Workspace!B18="","",Workspace!L18) | J21: ==IF(Workspace!B18="","",Workspace!M18) | K21: ==IF(Workspace!B18="","",Workspace!N18) | L21: ==IF(Workspace!B18="","",VLOOKUP(Workspace!N18,RecTable,2,FALSE))
H22: ==IF(Workspace!B19="","",Workspace!B19) | I22: ==IF(Workspace!B19="","",Workspace!L19) | J22: ==IF(Workspace!B19="","",Workspace!M19) | K22: ==IF(Workspace!B19="","",Workspace!N19) | L22: ==IF(Workspace!B19="","",VLOOKUP(Workspace!N19,RecTable,2,FALSE))
H23: ==IF(Workspace!B20="","",Workspace!B20) | I23: ==IF(Workspace!B20="","",Workspace!L20) | J23: ==IF(Workspace!B20="","",Workspace!M20) | K23: ==IF(Workspace!B20="","",Workspace!N20) | L23: ==IF(Workspace!B20="","",VLOOKUP(Workspace!N20,RecTable,2,FALSE))
H24: ==IF(Workspace!B21="","",Workspace!B21) | I24: ==IF(Workspace!B21="","",Workspace!L21) | J24: ==IF(Workspace!B21="","",Workspace!M21) | K24: ==IF(Workspace!B21="","",Workspace!N21) | L24: ==IF(Workspace!B21="","",VLOOKUP(Workspace!N21,RecTable,2,FALSE))
... H34: ==IF(Workspace!B31="","",Workspace!B31) | I34: ==IF(Workspace!B31="","",Workspace!L31) | J34: ==IF(Workspace!B31="","",Workspace!M31) | K34: ==IF(Workspace!B31="","",Workspace!N31) | L34: ==IF(Workspace!B31="","",VLOOKUP(Workspace!N31,RecTable,2,FALSE))

Sheet Reference
A1: Communities | C1: Charity Organization | D1: Agency (Inspector) | E1: Community Outreach Lead | F1: Competition | G1: Industry Consumers | H1: Board Member | J1: Americas | K1: United States | L1: National (all) | M1: High | N1: Active | P1: Proactively Defend | Q1: Defend | R1: Valuable Relationship | S1: Strategic Partner | U1: Proactively Defend | V1: Address Key Influencer: Launch plan to neutralize a major threat to the industry or company's license to operate; leverage reputation, resources, subject-matter experts, and other allied stakeholders to win. Measure and report on activity often.
A2: Government | C2: Church | D2: Agency (Permit Writer) | E2: Diversity & Inclusion Lead | F2: Supply Chain | G2: Current Customers | H2: Shareholder | J2: LATAM | K2: Canada | L2: Federal | M2: Medium | N2: Watch | P2: Defend | Q2: Protect | R2: Collaborate | S2: High Value Relationship | U2: Defend | V2: Neutralize Threat: Defend license to operate. Defend reputation against regular attacks from stakeholders with high influence who are unlikely to move toward positive support; discredit message or position. Measure and report on activity often.
A3: Our People | C3: Community Alliance | D3: City Council Member | E3: Executive | F3: Trade Association | G3: Future Customers | H3: Activist Shareholder | J3: EMEA | K3: Mexico | L3: State | M3: Low | N3: Dormant | P3: Protect | Q3: Respond | R3: Cooperate | S3: Collaborate | U3: Protect | V3: Mobilize Defense: Take action with internal resources and strategy. Defend reputation against regular attacks; manage expectations for changing stakeholder dynamic or group's influence in the community. Measure and report on activity regularly.
A4: Industry | C4: Higher Education | D4: City Government | E4: General Employee | F4: Channel Partners | G4: Lost Customers | H4: General Public Investor | J4: APJ | K4: Brazil | L4: Local | N4: Inactive | P4: Protect | Q4: Respond | R4: Cooperate | S4: Collaborate | U4: Respond | V4: Challenge Stakeholder: Implement plan to challenge misinformation; reduce stakeholder's ability to destabilize the business or challenge brand identity and reputation.
A5: Consumers | C5: K-12 Educator | D5: County Government | E5: Former Employee | F5: Industry Analysts | K5: Other Countries | P5: Identify | Q5: Identify | R5: Commit | S5: Commit | U5: Identify | V5: React To Issues Or Conflict: Work to neutralize threat; educate stakeholder; resolve or minimize the stakeholder's ability or willingness to maintain conflict. Assign internal staff, team, or working group to execute response.
A6: Investors | C6: Local Business | D6: County Supervisor | E6: Contractor | F6: Business Coalition | K6: Europe | P6: Monitor | Q6: Monitor | R6: Maintain | S6: Connect | U6: Monitor | V6: Plan Ahead, Listen: Map stakeholder and plan to respond in the event of change; assign internal staff, team, or working group to execute plan if necessary.
C7: Media | D7: Governor's Office | E7: Operations Manager | F7: Economic Development | K7: Middle East | U7: Maintain | V7: Take Steps To Introduce Our Vision And Values: Take simple steps to engage; educate and create awareness about the business; look for ways to increase alignment and the stakeholder's influence over time.
C8: Military Branch | D8: Judicial | E8: Marketing Manager | F8: Labor Union | K8: Africa | U8: Connect | V8: Prioritize Resources Elsewhere: Take no action. Prioritize time and resources elsewhere but monitor for any negative changes in alignment or improved influence in the community over time.
C9: Neighbor | D9: Mayor | E9: Sales Manager | K9: Emerging APAC | U9: Commit | V9: Understand Needs, Work Towards Common Purpose: Build greater understanding between our company and stakeholder groups; look for opportunities to continue education and alignment that could lead to improved collaboration or affinity toward the business.
C10: NGO | D10: Regulator (Federal) | E10: Retiree | K10: Japan | U10: Cooperate | V10: Existing Alignment Produces Some Favorable Outcomes: Some value already exists and should continue with moderate level of commitment; maintain existing level of relationship.
C11: Tribes | D11: Regulator (State) | U11: Collaborate | V11: Investing In Relationship Will Improve Our Business Or Reputation: Commitment important to our business; establish opportunities to work together and reap mutual benefits; leverage stakeholder's influence to increase our reputation.
C12: Veterans | D12: Regulator (Local) | U12: Valuable Relationship | V12: Stakeholder Important To Our Business Success: Stakeholder is an important surrogate, ally, or business partner. Investing in and growing this relationship proactively supports and defends the business and increases our reputation. Prioritize collaboration and deploying engagement strategies.
C13: Youth Program | D13: State Representative | U13: High Value Relationship | V13: Shared Value Introduced: Moderate shared value introduced; investing and growing this relationship produces value for our business and increases our reputation. Prioritize collaboration and engaging the stakeholder often to meet business and advocacy goals.
C14: Activist Organization | D14: State Senate | U14: Strategic Partner | V14: Shared Value Created: Shared value created. Formalize a working relationship or partnership with the stakeholder to produce and measure shared value; relationship grows the business, increases our reputation, and produces solutions.
C15: Activist Member | D15: US Congress
C16: General Public | D16: US Senate
